Workbook

Sheet ObservedDefoliations
A1: SimulationName | B1: Location | C1: WaterMgmt | D1: TreatNo | E1: Date | F1: DoY | G1: FarmingYear | H1: Season | I1: DaysSinceLastDefoliation | J1: DefoliatedWt | K1: CumDefoliatedWt
A2: RuakuraNo2WaterMgmtRainfed | B2: RuakuraNo2 | C2: Rainfed | D2: 4 | E2: 30147 | F2: =E2-DATE(YEAR(E2),1,0) -> 196 | G2: =YEAR(E2)+IF(MONTH(E2)<6,0,1) -> 1983 | H2: =IF(MONTH(E2)<3,"Summer",IF(MONTH(E2)<6,"Autumn",IF(MONTH(E2)<9,"Winter",IF(MONTH(E2)<12,"Spring","Summer")))) -> Winter | I2: 28 | J2: 318.2 | K2: =SUMIFS(J$2:J2,B$2:B2,B2,C$2:C2,C2,G$2:G2,G2) -> 318.2
A3: RuakuraNo2WaterMgmtRainfed | B3: RuakuraNo2 | C3: Rainfed | D3: 4 | E3: 30175 | F3: =E3-DATE(YEAR(E3),1,0) -> 224 | G3: =YEAR(E3)+IF(MONTH(E3)<6,0,1) -> 1983 | H3: =IF(MONTH(E3)<3,"Summer",IF(MONTH(E3)<6,"Autumn",IF(MONTH(E3)<9,"Winter",IF(MONTH(E3)<12,"Spring","Summer")))) -> Winter | I3: 28 | J3: 694.9 | K3: =SUMIFS(J$2:J3,B$2:B3,B3,C$2:C3,C3,G$2:G3,G3) -> 1013.1
A4: RuakuraNo2WaterMgmtRainfed | B4: RuakuraNo2 | C4: Rainfed | D4: 4 | E4: 30203 | F4: =E4-DATE(YEAR(E4),1,0) -> 252 | G4: =YEAR(E4)+IF(MONTH(E4)<6,0,1) -> 1983 | H4: =IF(MONTH(E4)<3,"Summer",IF(MONTH(E4)<6,"Autumn",IF(MONTH(E4)<9,"Winter",IF(MONTH(E4)<12,"Spring","Summer")))) -> Spring | I4: 28 | J4: 1279.9 | K4: =SUMIFS(J$2:J4,B$2:B4,B4,C$2:C4,C4,G$2:G4,G4) -> 2293
A5: RuakuraNo2WaterMgmtRainfed | B5: RuakuraNo2 | C5: Rainfed | D5: 4 | E5: 30231 | F5: =E5-DATE(YEAR(E5),1,0) -> 280 | G5: =YEAR(E5)+IF(MONTH(E5)<6,0,1) -> 1983 | H5: =IF(MONTH(E5)<3,"Summer",IF(MONTH(E5)<6,"Autumn",IF(MONTH(E5)<9,"Winter",IF(MONTH(E5)<12,"Spring","Summer")))) -> Spring | I5: 28 | J5: 2270.5 | K5: =SUMIFS(J$2:J5,B$2:B5,B5,C$2:C5,C5,G$2:G5,G5) -> 4563.5
A6: RuakuraNo2WaterMgmtRainfed | B6: RuakuraNo2 | C6: Rainfed | D6: 4 | E6: 30259 | F6: =E6-DATE(YEAR(E6),1,0) -> 308 | G6: =YEAR(E6)+IF(MONTH(E6)<6,0,1) -> 1983 | H6: =IF(MONTH(E6)<3,"Summer",IF(MONTH(E6)<6,"Autumn",IF(MONTH(E6)<9,"Winter",IF(MONTH(E6)<12,"Spring","Summer")))) -> Spring | I6: 28 | J6: 1982.4 | K6: =SUMIFS(J$2:J6,B$2:B6,B6,C$2:C6,C6,G$2:G6,G6) -> 6545.9
A7: RuakuraNo2WaterMgmtRainfed | B7: RuakuraNo2 | C7: Rainfed | D7: 4 | E7: 30287 | F7: =E7-DATE(YEAR(E7),1,0) -> 336 | G7: =YEAR(E7)+IF(MONTH(E7)<6,0,1) -> 1983 | H7: =IF(MONTH(E7)<3,"Summer",IF(MONTH(E7)<6,"Autumn",IF(MONTH(E7)<9,"Winter",IF(MONTH(E7)<12,"Spring","Summer")))) -> Summer | I7: 28 | J7: 2190.8 | K7: =SUMIFS(J$2:J7,B$2:B7,B7,C$2:C7,C7,G$2:G7,G7) -> 8736.7
A8: RuakuraNo2WaterMgmtRainfed | B8: RuakuraNo2 | C8: Rainfed | D8: 4 | E8: 30315 | F8: =E8-DATE(YEAR(E8),1,0) -> 364 | G8: =YEAR(E8)+IF(MONTH(E8)<6,0,1) -> 1983 | H8: =IF(MONTH(E8)<3,"Summer",IF(MONTH(E8)<6,"Autumn",IF(MONTH(E8)<9,"Winter",IF(MONTH(E8)<12,"Spring","Summer")))) -> Summer | I8: 28 | J8: 2200.1 | K8: =SUMIFS(J$2:J8,B$2:B8,B8,C$2:C8,C8,G$2:G8,G8) -> 10936.8
A9: RuakuraNo2WaterMgmtRainfed | B9: RuakuraNo2 | C9: Rainfed | D9: 4 | E9: 30343 | F9: =E9-DATE(YEAR(E9),1,0) -> 27 | G9: =YEAR(E9)+IF(MONTH(E9)<6,0,1) -> 1983 | H9: =IF(MONTH(E9)<3,"Summer",IF(MONTH(E9)<6,"Autumn",IF(MONTH(E9)<9,"Winter",IF(MONTH(E9)<12,"Spring","Summer")))) -> Summer | I9: 28 | J9: 1894.6 | K9: =SUMIFS(J$2:J9,B$2:B9,B9,C$2:C9,C9,G$2:G9,G9) -> 12831.4
A10: RuakuraNo2WaterMgmtRainfed | B10: RuakuraNo2 | C10: Rainfed | D10: 4 | E10: 30371 | F10: =E10-DATE(YEAR(E10),1,0) -> 55 | G10: =YEAR(E10)+IF(MONTH(E10)<6,0,1) -> 1983 | H10: =IF(MONTH(E10)<3,"Summer",IF(MONTH(E10)<6,"Autumn",IF(MONTH(E10)<9,"Winter",IF(MONTH(E10)<12,"Spring","Summer")))) -> Summer | I10: 28 | J10: 1014.7 | K10: =SUMIFS(J$2:J10,B$2:B10,B10,C$2:C10,C10,G$2:G10,G10) -> 13846.1
A11: RuakuraNo2WaterMgmtRainfed | B11: RuakuraNo2 | C11: Rainfed | D11: 4 | E11: 30399 | F11: =E11-DATE(YEAR(E11),1,0) -> 83 | G11: =YEAR(E11)+IF(MONTH(E11)<6,0,1) -> 1983 | H11: =IF(MONTH(E11)<3,"Summer",IF(MONTH(E11)<6,"Autumn",IF(MONTH(E11)<9,"Winter",IF(MONTH(E11)<12,"Spring","Summer")))) -> Autumn | I11: 28 | J11: 680.8 | K11: =SUMIFS(J$2:J11,B$2:B11,B11,C$2:C11,C11,G$2:G11,G11) -> 14526.9
A12: RuakuraNo2WaterMgmtRainfed | B12: RuakuraNo2 | C12: Rainfed | D12: 4 | E12: 30427 | F12: =E12-DATE(YEAR(E12),1,0) -> 111 | G12: =YEAR(E12)+IF(MONTH(E12)<6,0,1) -> 1983 | H12: =IF(MONTH(E12)<3,"Summer",IF(MONTH(E12)<6,"Autumn",IF(MONTH(E12)<9,"Winter",IF(MONTH(E12)<12,"Spring","Summer")))) -> Autumn | I12: 28 | J12: 1255.9 | K12: =SUMIFS(J$2:J12,B$2:B12,B12,C$2:C12,C12,G$2:G12,G12) -> 15782.8
A13: RuakuraNo2WaterMgmtRainfed | B13: RuakuraNo2 | C13: Rainfed | D13: 4 | E13: 30455 | F13: =E13-DATE(YEAR(E13),1,0) -> 139 | G13: =YEAR(E13)+IF(MONTH(E13)<6,0,1) -> 1983 | H13: =IF(MONTH(E13)<3,"Summer",IF(MONTH(E13)<6,"Autumn",IF(MONTH(E13)<9,"Winter",IF(MONTH(E13)<12,"Spring","Summer")))) -> Autumn | I13: 28 | J13: 1009.4 | K13: =SUMIFS(J$2:J13,B$2:B13,B13,C$2:C13,C13,G$2:G13,G13) -> 16792.2
... A693: WinchmoreWaterMgmtIrrigated | B693: Whichmore | C693: Irrigated | D693: 3 | E693: 37713 | F693: =E693-DATE(YEAR(E693),1,0) -> 92 | G693: =YEAR(E693)+IF(MONTH(E693)<6,0,1) -> 2003 | H693: =IF(MONTH(E693)<3,"Summer",IF(MONTH(E693)<6,"Autumn",IF(MONTH(E693)<9,"Winter",IF(MONTH(E693)<12,"Spring","Summer")))) -> Autumn | I693: 54 | J693: 2246.4 | K693: =SUMIFS(J$2:J693,B$2:B693,B693,C$2:C693,C693,G$2:G693,G693) -> 11039.1

Sheet ObservedAnnualMeans
A1: SimulationName | B1: Location | C1: WaterMgmt | D1: TreatNo | E1: Date | F1: DoY | G1: FarmingYear | H1: NumData | I1: DaysBetweenDefoliations | J1: AvgDefoliatedWt | K1: CumDefoliatedWt
A2: RuakuraNo2WaterMgmtRainfed | B2: RuakuraNo2 | C2: Rainfed | D2: 4 | E2: 30467 | F2: =E2-DATE(YEAR(E2),1,0) -> 151 | G2: 1983 | H2: =COUNTIFS(ObservedDefoliations!$A$2:$A$700,$A2,ObservedDefoliations!$B$2:$B$700,$B2,ObservedDefoliations!$C$2:$C$700,$C2,ObservedDefoliations!$G$2:$G$700,$G2) -> 12 | I2: =AVERAGEIFS(ObservedDefoliations!I$2:I$700,ObservedDefoliations!$A$2:$A$700,$A2,ObservedDefoliations!$B$2:$B$700,$B2,ObservedDefoliations!$C$2:$C$700,$C2,ObservedDefoliations!$G$2:$G$700,$G2) -> 28 | J2: =AVERAGEIFS(ObservedDefoliations!J$2:J$700,ObservedDefoliations!$A$2:$A$700,$A2,ObservedDefoliations!$B$2:$B$700,$B2,ObservedDefoliations!$C$2:$C$700,$C2,ObservedDefoliations!$G$2:$G$700,$G2) -> 1399.35 | K2: =SUMIFS(ObservedDefoliations!J$2:J$700,ObservedDefoliations!$A$2:$A$700,$A2,ObservedDefoliations!$B$2:$B$700,$B2,ObservedDefoliations!$C$2:$C$700,$C2,ObservedDefoliations!$G$2:$G$700,$G2) -> 16792.2
A3: RuakuraNo2WaterMgmtRainfed | B3: RuakuraNo2 | C3: Rainfed | D3: 4 | E3: 30833 | F3: =E3-DATE(YEAR(E3),1,0) -> 152 | G3: 1984 | H3: =COUNTIFS(ObservedDefoliations!$A$2:$A$700,$A3,ObservedDefoliations!$B$2:$B$700,$B3,ObservedDefoliations!$C$2:$C$700,$C3,ObservedDefoliations!$G$2:$G$700,$G3) -> 13 | I3: =AVERAGEIFS(ObservedDefoliations!$I$2:$I$700,ObservedDefoliations!$A$2:$A$700,$A3,ObservedDefoliations!$B$2:$B$700,$B3,ObservedDefoliations!$C$2:$C$700,$C3,ObservedDefoliations!$G$2:$G$700,$G3) -> 28 | J3: =AVERAGEIFS(ObservedDefoliations!J$2:J$700,ObservedDefoliations!$A$2:$A$700,$A3,ObservedDefoliations!$B$2:$B$700,$B3,ObservedDefoliations!$C$2:$C$700,$C3,ObservedDefoliations!$G$2:$G$700,$G3) -> 1291.3692 | K3: =SUMIFS(ObservedDefoliations!J$2:J$700,ObservedDefoliations!$A$2:$A$700,$A3,ObservedDefoliations!$B$2:$B$700,$B3,ObservedDefoliations!$C$2:$C$700,$C3,ObservedDefoliations!$G$2:$G$700,$G3) -> 16787.8
A4: RuakuraNo2WaterMgmtRainfed | B4: RuakuraNo2 | C4: Rainfed | D4: 4 | E4: 31198 | F4: =E4-DATE(YEAR(E4),1,0) -> 151 | G4: 1985 | H4: =COUNTIFS(ObservedDefoliations!$A$2:$A$700,$A4,ObservedDefoliations!$B$2:$B$700,$B4,ObservedDefoliations!$C$2:$C$700,$C4,ObservedDefoliations!$G$2:$G$700,$G4) -> 13 | I4: =AVERAGEIFS(ObservedDefoliations!$I$2:$I$700,ObservedDefoliations!$A$2:$A$700,$A4,ObservedDefoliations!$B$2:$B$700,$B4,ObservedDefoliations!$C$2:$C$700,$C4,ObservedDefoliations!$G$2:$G$700,$G4) -> 28 | J4: =AVERAGEIFS(ObservedDefoliations!J$2:J$700,ObservedDefoliations!$A$2:$A$700,$A4,ObservedDefoliations!$B$2:$B$700,$B4,ObservedDefoliations!$C$2:$C$700,$C4,ObservedDefoliations!$G$2:$G$700,$G4) -> 1301.0923 | K4: =SUMIFS(ObservedDefoliations!J$2:J$700,ObservedDefoliations!$A$2:$A$700,$A4,ObservedDefoliations!$B$2:$B$700,$B4,ObservedDefoliations!$C$2:$C$700,$C4,ObservedDefoliations!$G$2:$G$700,$G4) -> 16914.2
A5: RuakuraNo2WaterMgmtRainfed | B5: RuakuraNo2 | C5: Rainfed | D5: 4 | E5: 31563 | F5: =E5-DATE(YEAR(E5),1,0) -> 151 | G5: 1986 | H5: =COUNTIFS(ObservedDefoliations!$A$2:$A$700,$A5,ObservedDefoliations!$B$2:$B$700,$B5,ObservedDefoliations!$C$2:$C$700,$C5,ObservedDefoliations!$G$2:$G$700,$G5) -> 13 | I5: =AVERAGEIFS(ObservedDefoliations!$I$2:$I$700,ObservedDefoliations!$A$2:$A$700,$A5,ObservedDefoliations!$B$2:$B$700,$B5,ObservedDefoliations!$C$2:$C$700,$C5,ObservedDefoliations!$G$2:$G$700,$G5) -> 28 | J5: =AVERAGEIFS(ObservedDefoliations!J$2:J$700,ObservedDefoliations!$A$2:$A$700,$A5,ObservedDefoliations!$B$2:$B$700,$B5,ObservedDefoliations!$C$2:$C$700,$C5,ObservedDefoliations!$G$2:$G$700,$G5) -> 1254.9308 | K5: =SUMIFS(ObservedDefoliations!J$2:J$700,ObservedDefoliations!$A$2:$A$700,$A5,ObservedDefoliations!$B$2:$B$700,$B5,ObservedDefoliations!$C$2:$C$700,$C5,ObservedDefoliations!$G$2:$G$700,$G5) -> 16314.1
A6: RuakuraNo2WaterMgmtRainfed | B6: RuakuraNo2 | C6: Rainfed | D6: 4 | E6: 31928 | F6: =E6-DATE(YEAR(E6),1,0) -> 151 | G6: 1987 | H6: =COUNTIFS(ObservedDefoliations!$A$2:$A$700,$A6,ObservedDefoliations!$B$2:$B$700,$B6,ObservedDefoliations!$C$2:$C$700,$C6,ObservedDefoliations!$G$2:$G$700,$G6) -> 13 | I6: =AVERAGEIFS(ObservedDefoliations!$I$2:$I$700,ObservedDefoliations!$A$2:$A$700,$A6,ObservedDefoliations!$B$2:$B$700,$B6,ObservedDefoliations!$C$2:$C$700,$C6,ObservedDefoliations!$G$2:$G$700,$G6) -> 28 | J6: =AVERAGEIFS(ObservedDefoliations!J$2:J$700,ObservedDefoliations!$A$2:$A$700,$A6,ObservedDefoliations!$B$2:$B$700,$B6,ObservedDefoliations!$C$2:$C$700,$C6,ObservedDefoliations!$G$2:$G$700,$G6) -> 1158.0077 | K6: =SUMIFS(ObservedDefoliations!J$2:J$700,ObservedDefoliations!$A$2:$A$700,$A6,ObservedDefoliations!$B$2:$B$700,$B6,ObservedDefoliations!$C$2:$C$700,$C6,ObservedDefoliations!$G$2:$G$700,$G6) -> 15054.1
A7: RuakuraNo2WaterMgmtRainfed | B7: RuakuraNo2 | C7: Rainfed | D7: 4 | E7: 32294 | F7: =E7-DATE(YEAR(E7),1,0) -> 152 | G7: 1988 | H7: =COUNTIFS(ObservedDefoliations!$A$2:$A$700,$A7,ObservedDefoliations!$B$2:$B$700,$B7,ObservedDefoliations!$C$2:$C$700,$C7,ObservedDefoliations!$G$2:$G$700,$G7) -> 13 | I7: =AVERAGEIFS(ObservedDefoliations!$I$2:$I$700,ObservedDefoliations!$A$2:$A$700,$A7,ObservedDefoliations!$B$2:$B$700,$B7,ObservedDefoliations!$C$2:$C$700,$C7,ObservedDefoliations!$G$2:$G$700,$G7) -> 28 | J7: =AVERAGEIFS(ObservedDefoliations!J$2:J$700,ObservedDefoliations!$A$2:$A$700,$A7,ObservedDefoliations!$B$2:$B$700,$B7,ObservedDefoliations!$C$2:$C$700,$C7,ObservedDefoliations!$G$2:$G$700,$G7) -> 1035.7077 | K7: =SUMIFS(ObservedDefoliations!J$2:J$700,ObservedDefoliations!$A$2:$A$700,$A7,ObservedDefoliations!$B$2:$B$700,$B7,ObservedDefoliations!$C$2:$C$700,$C7,ObservedDefoliations!$G$2:$G$700,$G7) -> 13464.2
A8: RuakuraNo2WaterMgmtRainfed | B8: RuakuraNo2 | C8: Rainfed | D8: 4 | E8: 32659 | F8: =E8-DATE(YEAR(E8),1,0) -> 151 | G8: 1989 | H8: =COUNTIFS(ObservedDefoliations!$A$2:$A$700,$A8,ObservedDefoliations!$B$2:$B$700,$B8,ObservedDefoliations!$C$2:$C$700,$C8,ObservedDefoliations!$G$2:$G$700,$G8) -> 13 | I8: =AVERAGEIFS(ObservedDefoliations!$I$2:$I$700,ObservedDefoliations!$A$2:$A$700,$A8,ObservedDefoliations!$B$2:$B$700,$B8,ObservedDefoliations!$C$2:$C$700,$C8,ObservedDefoliations!$G$2:$G$700,$G8) -> 28 | J8: =AVERAGEIFS(ObservedDefoliations!J$2:J$700,ObservedDefoliations!$A$2:$A$700,$A8,ObservedDefoliations!$B$2:$B$700,$B8,ObservedDefoliations!$C$2:$C$700,$C8,ObservedDefoliations!$G$2:$G$700,$G8) -> 1120.5 | K8: =SUMIFS(ObservedDefoliations!J$2:J$700,ObservedDefoliations!$A$2:$A$700,$A8,ObservedDefoliations!$B$2:$B$700,$B8,ObservedDefoliations!$C$2:$C$700,$C8,ObservedDefoliations!$G$2:$G$700,$G8) -> 14566.5
A9: RuakuraNo2WaterMgmtRainfed | B9: RuakuraNo2 | C9: Rainfed | D9: 4 | E9: 33024 | F9: =E9-DATE(YEAR(E9),1,0) -> 151 | G9: 1990 | H9: =COUNTIFS(ObservedDefoliations!$A$2:$A$700,$A9,ObservedDefoliations!$B$2:$B$700,$B9,ObservedDefoliations!$C$2:$C$700,$C9,ObservedDefoliations!$G$2:$G$700,$G9) -> 13 | I9: =AVERAGEIFS(ObservedDefoliations!$I$2:$I$700,ObservedDefoliations!$A$2:$A$700,$A9,ObservedDefoliations!$B$2:$B$700,$B9,ObservedDefoliations!$C$2:$C$700,$C9,ObservedDefoliations!$G$2:$G$700,$G9) -> 27.923077 | J9: =AVERAGEIFS(ObservedDefoliations!J$2:J$700,ObservedDefoliations!$A$2:$A$700,$A9,ObservedDefoliations!$B$2:$B$700,$B9,ObservedDefoliations!$C$2:$C$700,$C9,ObservedDefoliations!$G$2:$G$700,$G9) -> 1168.7846 | K9: =SUMIFS(ObservedDefoliations!J$2:J$700,ObservedDefoliations!$A$2:$A$700,$A9,ObservedDefoliations!$B$2:$B$700,$B9,ObservedDefoliations!$C$2:$C$700,$C9,ObservedDefoliations!$G$2:$G$700,$G9) -> 15194.2
A10: RuakuraNo2WaterMgmtRainfed | B10: RuakuraNo2 | C10: Rainfed | D10: 4 | E10: 33389 | F10: =E10-DATE(YEAR(E10),1,0) -> 151 | G10: 1991 | H10: =COUNTIFS(ObservedDefoliations!$A$2:$A$700,$A10,ObservedDefoliations!$B$2:$B$700,$B10,ObservedDefoliations!$C$2:$C$700,$C10,ObservedDefoliations!$G$2:$G$700,$G10) -> 13 | I10: =AVERAGEIFS(ObservedDefoliations!$I$2:$I$700,ObservedDefoliations!$A$2:$A$700,$A10,ObservedDefoliations!$B$2:$B$700,$B10,ObservedDefoliations!$C$2:$C$700,$C10,ObservedDefoliations!$G$2:$G$700,$G10) -> 28.076923 | J10: =AVERAGEIFS(ObservedDefoliations!J$2:J$700,ObservedDefoliations!$A$2:$A$700,$A10,ObservedDefoliations!$B$2:$B$700,$B10,ObservedDefoliations!$C$2:$C$700,$C10,ObservedDefoliations!$G$2:$G$700,$G10) -> 1255.2154 | K10: =SUMIFS(ObservedDefoliations!J$2:J$700,ObservedDefoliations!$A$2:$A$700,$A10,ObservedDefoliations!$B$2:$B$700,$B10,ObservedDefoliations!$C$2:$C$700,$C10,ObservedDefoliations!$G$2:$G$700,$G10) -> 16317.8
A11: RuakuraNo2WaterMgmtRainfed | B11: RuakuraNo2 | C11: Rainfed | D11: 4 | E11: 33755 | F11: =E11-DATE(YEAR(E11),1,0) -> 152 | G11: 1992 | H11: =COUNTIFS(ObservedDefoliations!$A$2:$A$700,$A11,ObservedDefoliations!$B$2:$B$700,$B11,ObservedDefoliations!$C$2:$C$700,$C11,ObservedDefoliations!$G$2:$G$700,$G11) -> 13 | I11: =AVERAGEIFS(ObservedDefoliations!$I$2:$I$700,ObservedDefoliations!$A$2:$A$700,$A11,ObservedDefoliations!$B$2:$B$700,$B11,ObservedDefoliations!$C$2:$C$700,$C11,ObservedDefoliations!$G$2:$G$700,$G11) -> 28 | J11: =AVERAGEIFS(ObservedDefoliations!J$2:J$700,ObservedDefoliations!$A$2:$A$700,$A11,ObservedDefoliations!$B$2:$B$700,$B11,ObservedDefoliations!$C$2:$C$700,$C11,ObservedDefoliations!$G$2:$G$700,$G11) -> 1047.2462 | K11: =SUMIFS(ObservedDefoliations!J$2:J$700,ObservedDefoliations!$A$2:$A$700,$A11,ObservedDefoliations!$B$2:$B$700,$B11,ObservedDefoliations!$C$2:$C$700,$C11,ObservedDefoliations!$G$2:$G$700,$G11) -> 13614.2
A12: WinchmoreWaterMgmtRainfed | B12: Whichmore | C12: Rainfed | D12: 0 | E12: 24623 | F12: =E12-DATE(YEAR(E12),1,0) -> 151 | G12: 1967 | H12: =COUNTIFS(ObservedDefoliations!$A$2:$A$700,$A12,ObservedDefoliations!$B$2:$B$700,$B12,ObservedDefoliations!$C$2:$C$700,$C12,ObservedDefoliations!$G$2:$G$700,$G12) -> 9 | I12: =AVERAGEIFS(ObservedDefoliations!$I$2:$I$700,ObservedDefoliations!$A$2:$A$700,$A12,ObservedDefoliations!$B$2:$B$700,$B12,ObservedDefoliations!$C$2:$C$700,$C12,ObservedDefoliations!$G$2:$G$700,$G12) -> 33.888889 | J12: =AVERAGEIFS(ObservedDefoliations!J$2:J$700,ObservedDefoliations!$A$2:$A$700,$A12,ObservedDefoliations!$B$2:$B$700,$B12,ObservedDefoliations!$C$2:$C$700,$C12,ObservedDefoliations!$G$2:$G$700,$G12) -> 707.4 | K12: =SUMIFS(ObservedDefoliations!J$2:J$700,ObservedDefoliations!$A$2:$A$700,$A12,ObservedDefoliations!$B$2:$B$700,$B12,ObservedDefoliations!$C$2:$C$700,$C12,ObservedDefoliations!$G$2:$G$700,$G12) -> 6366.6
A13: WinchmoreWaterMgmtRainfed | B13: Whichmore | C13: Rainfed | D13: 0 | E13: 24989 | F13: =E13-DATE(YEAR(E13),1,0) -> 152 | G13: 1968 | H13: =COUNTIFS(ObservedDefoliations!$A$2:$A$700,$A13,ObservedDefoliations!$B$2:$B$700,$B13,ObservedDefoliations!$C$2:$C$700,$C13,ObservedDefoliations!$G$2:$G$700,$G13) -> 9 | I13: =AVERAGEIFS(ObservedDefoliations!$I$2:$I$700,ObservedDefoliations!$A$2:$A$700,$A13,ObservedDefoliations!$B$2:$B$700,$B13,ObservedDefoliations!$C$2:$C$700,$C13,ObservedDefoliations!$G$2:$G$700,$G13) -> 40.333333 | J13: =AVERAGEIFS(ObservedDefoliations!J$2:J$700,ObservedDefoliations!$A$2:$A$700,$A13,ObservedDefoliations!$B$2:$B$700,$B13,ObservedDefoliations!$C$2:$C$700,$C13,ObservedDefoliations!$G$2:$G$700,$G13) -> 874.85556 | K13: =SUMIFS(ObservedDefoliations!J$2:J$700,ObservedDefoliations!$A$2:$A$700,$A13,ObservedDefoliations!$B$2:$B$700,$B13,ObservedDefoliations!$C$2:$C$700,$C13,ObservedDefoliations!$G$2:$G$700,$G13) -> 7873.7
A14: WinchmoreWaterMgmtRainfed | B14: Whichmore | C14: Rainfed | D14: 0 | E14: 25354 | F14: =E14-DATE(YEAR(E14),1,0) -> 151 | G14: 1969 | H14: =COUNTIFS(ObservedDefoliations!$A$2:$A$700,$A14,ObservedDefoliations!$B$2:$B$700,$B14,ObservedDefoliations!$C$2:$C$700,$C14,ObservedDefoliations!$G$2:$G$700,$G14) -> 10 | I14: =AVERAGEIFS(ObservedDefoliations!$I$2:$I$700,ObservedDefoliations!$A$2:$A$700,$A14,ObservedDefoliations!$B$2:$B$700,$B14,ObservedDefoliations!$C$2:$C$700,$C14,ObservedDefoliations!$G$2:$G$700,$G14) -> 40.9 | J14: =AVERAGEIFS(ObservedDefoliations!J$2:J$700,ObservedDefoliations!$A$2:$A$700,$A14,ObservedDefoliations!$B$2:$B$700,$B14,ObservedDefoliations!$C$2:$C$700,$C14,ObservedDefoliations!$G$2:$G$700,$G14) -> 646.49 | K14: =SUMIFS(ObservedDefoliations!J$2:J$700,ObservedDefoliations!$A$2:$A$700,$A14,ObservedDefoliations!$B$2:$B$700,$B14,ObservedDefoliations!$C$2:$C$700,$C14,ObservedDefoliations!$G$2:$G$700,$G14) -> 6464.9
... A83: WinchmoreWaterMgmtIrrigated | B83: Whichmore | C83: Irrigated | D83: 3 | E83: 37772 | F83: =E83-DATE(YEAR(E83),1,0) -> 151 | G83: 2003 | H83: =COUNTIFS(ObservedDefoliations!$A$2:$A$700,$A83,ObservedDefoliations!$B$2:$B$700,$B83,ObservedDefoliations!$C$2:$C$700,$C83,ObservedDefoliations!$G$2:$G$700,$G83) -> 6 | I83: =AVERAGEIFS(ObservedDefoliations!$I$2:$I$700,ObservedDefoliations!$A$2:$A$700,$A83,ObservedDefoliations!$B$2:$B$700,$B83,ObservedDefoliations!$C$2:$C$700,$C83,ObservedDefoliations!$G$2:$G$700,$G83) -> 52.833333 | J83: =AVERAGEIFS(ObservedDefoliations!J$2:J$700,ObservedDefoliations!$A$2:$A$700,$A83,ObservedDefoliations!$B$2:$B$700,$B83,ObservedDefoliations!$C$2:$C$700,$C83,ObservedDefoliations!$G$2:$G$700,$G83) -> 1839.85 | K83: =SUMIFS(ObservedDefoliations!J$2:J$700,ObservedDefoliations!$A$2:$A$700,$A83,ObservedDefoliations!$B$2:$B$700,$B83,ObservedDefoliations!$C$2:$C$700,$C83,ObservedDefoliations!$G$2:$G$700,$G83) -> 11039.1

Sheet ObservedSpeciesData
A1: SimulationName | B1: Source | C1: ForageTreat | D1: Date | E1: Rep | F1: NRate | G1: GrowthSeason | H1: Season | I1: RegrowthRotation | J1: EvalStage | K1: ActualNRate | L1: AboveGroundWt_kgha | M1: AbovegroundWt | N1: HarvestedWt_kgha | O1: DefoliatedWt | P1: CumDefoliatedWt | Q1: Population | R1: WhiteCloverFraction | S1: OtherSpeciesFraction | T1: DeadMaterialFraction | U1: CloverContent | V1: ADF % | W1: WSC% | X1: DOMD% | Y1: NDF% | Z1: OM% | AA1: CP% | AB1: HerbageNConc | AC1: AbovegroundLive.NConc | AD1: ME | AE1: DMContent | AF1: LAI | AG1: LightExtinctionCoefficient | AH1: DefoliatedN | AI1: CumDefoliatedN | AJ1: Nvals
A2: FRNLLincolnWCloverNRate0 | B2: LU_GEdwards | C2: WhiteClover | D2: 41935 | E2: 1 | F2: 0 | G2: 2014/15 | H2: Spring | I2: 1 | J2: Harvest | K2: 0 | M2: =IF(ISNUMBER(L2),L2/10,"") | N2: 2178.8823 | O2: =IF(ISNUMBER(N2),N2/10,"") -> 217.88823 | P2: =IF(ISNUMBER(O2),SUMIFS(O$1:$O2,A$1:$A2,A2,C$1:$C2,C2,G$1:$G2,G2,E$1:$E2,E2),"") -> 217.88823 | U2: =IF(ISNUMBER(R2),R2/100,"") | V2: 19.739852 | W2: 13.138709 | X2: 75.190197 | Y2: 26.306177 | Z2: 87.529396 | AA2: 24.376532 | AB2: 0.039002451 | AC2: =IF(ISNUMBER(AB2),AB2,"") -> 0.039002451 | AD2: 12.030432 | AE2: 19.798498 | AH2: =IF(AND(ISNUMBER(AB2),ISNUMBER(O2)),ROUND(O2*AB2,3),"") -> 8.498 | AI2: =IF(ISNUMBER(AH2),SUMIFS($AH$1:AH2,$A$1:A2,A2,C$1:$C2,C2,$G$1:G2,G2,$E$1:E2,E2),"") -> 8.498 | AJ2: =COUNT(K2:AI2) -> 16
A3: FRNLLincolnWCloverNRate50 | B3: LU_GEdwards | C3: WhiteClover | D3: 41935 | E3: 1 | F3: 50 | G3: 2014/15 | H3: Spring | I3: 1 | J3: Harvest | K3: 45 | M3: =IF(ISNUMBER(L3),L3/10,"") | N3: 2200.2351 | O3: =IF(ISNUMBER(N3),N3/10,"") -> 220.02351 | P3: =IF(ISNUMBER(O3),SUMIFS(O$1:$O3,A$1:$A3,A3,C$1:$C3,C3,G$1:$G3,G3,E$1:$E3,E3),"") -> 220.02351 | U3: =IF(ISNUMBER(R3),R3/100,"") | V3: 19.165732 | W3: 14.484433 | X3: 77.041466 | Y3: 25.048759 | Z3: 89.065754 | AA3: 25.008219 | AB3: 0.04001315 | AC3: =IF(ISNUMBER(AB3),AB3,"") -> 0.04001315 | AD3: 12.326635 | AE3: 23.000246 | AH3: =IF(AND(ISNUMBER(AB3),ISNUMBER(O3)),ROUND(O3*AB3,3),"") -> 8.804 | AI3: =IF(ISNUMBER(AH3),SUMIFS($AH$1:AH3,$A$1:A3,A3,C$1:$C3,C3,$G$1:G3,G3,$E$1:E3,E3),"") -> 8.804 | AJ3: =COUNT(K3:AI3) -> 16
A4: FRNLLincolnWCloverNRate100 | B4: LU_GEdwards | C4: WhiteClover | D4: 41935 | E4: 1 | F4: 100 | G4: 2014/15 | H4: Spring | I4: 1 | J4: Harvest | K4: 78 | M4: =IF(ISNUMBER(L4),L4/10,"") | N4: 2790.4172 | O4: =IF(ISNUMBER(N4),N4/10,"") -> 279.04172 | P4: =IF(ISNUMBER(O4),SUMIFS(O$1:$O4,A$1:$A4,A4,C$1:$C4,C4,G$1:$G4,G4,E$1:$E4,E4),"") -> 279.04172 | U4: =IF(ISNUMBER(R4),R4/100,"") | V4: 18.411832 | W4: 14.453085 | X4: 79.648552 | Y4: 24.686691 | Z4: 89.387302 | AA4: 26.222234 | AB4: 0.041955574 | AC4: =IF(ISNUMBER(AB4),AB4,"") -> 0.041955574 | AD4: 12.743768 | AE4: 21.403769 | AH4: =IF(AND(ISNUMBER(AB4),ISNUMBER(O4)),ROUND(O4*AB4,3),"") -> 11.707 | AI4: =IF(ISNUMBER(AH4),SUMIFS($AH$1:AH4,$A$1:A4,A4,C$1:$C4,C4,$G$1:G4,G4,$E$1:E4,E4),"") -> 11.707 | AJ4: =COUNT(K4:AI4) -> 16
A5: FRNLLincolnWCloverNRate200 | B5: LU_GEdwards | C5: WhiteClover | D5: 41935 | E5: 1 | F5: 200 | G5: 2014/15 | H5: Spring | I5: 1 | J5: Harvest | K5: 156 | M5: =IF(ISNUMBER(L5),L5/10,"") | N5: 2287.3347 | O5: =IF(ISNUMBER(N5),N5/10,"") -> 228.73347 | P5: =IF(ISNUMBER(O5),SUMIFS(O$1:$O5,A$1:$A5,A5,C$1:$C5,C5,G$1:$G5,G5,E$1:$E5,E5),"") -> 228.73347 | U5: =IF(ISNUMBER(R5),R5/100,"") | V5: 19.089677 | W5: 12.664886 | X5: 77.250782 | Y5: 27.113443 | Z5: 87.804222 | AA5: 24.583626 | AB5: 0.039333801 | AC5: =IF(ISNUMBER(AB5),AB5,"") -> 0.039333801 | AD5: 12.360125 | AE5: 21.274915 | AH5: =IF(AND(ISNUMBER(AB5),ISNUMBER(O5)),ROUND(O5*AB5,3),"") -> 8.997 | AI5: =IF(ISNUMBER(AH5),SUMIFS($AH$1:AH5,$A$1:A5,A5,C$1:$C5,C5,$G$1:G5,G5,$E$1:E5,E5),"") -> 8.997 | AJ5: =COUNT(K5:AI5) -> 16
A6: FRNLLincolnWCloverNRate350 | B6: LU_GEdwards | C6: WhiteClover | D6: 41935 | E6: 1 | F6: 350 | G6: 2014/15 | H6: Spring | I6: 1 | J6: Harvest | K6: 272 | M6: =IF(ISNUMBER(L6),L6/10,"") | N6: 2765.0213 | O6: =IF(ISNUMBER(N6),N6/10,"") -> 276.50213 | P6: =IF(ISNUMBER(O6),SUMIFS(O$1:$O6,A$1:$A6,A6,C$1:$C6,C6,G$1:$G6,G6,E$1:$E6,E6),"") -> 276.50213 | U6: =IF(ISNUMBER(R6),R6/100,"") | V6: 20.203855 | W6: 13.726878 | X6: 74.569794 | Y6: 26.440729 | Z6: 87.497662 | AA6: 24.502426 | AB6: 0.039203882 | AC6: =IF(ISNUMBER(AB6),AB6,"") -> 0.039203882 | AD6: 11.931167 | AE6: 21.20897 | AH6: =IF(AND(ISNUMBER(AB6),ISNUMBER(O6)),ROUND(O6*AB6,3),"") -> 10.84 | AI6: =IF(ISNUMBER(AH6),SUMIFS($AH$1:AH6,$A$1:A6,A6,C$1:$C6,C6,$G$1:G6,G6,$E$1:E6,E6),"") -> 10.84 | AJ6: =COUNT(K6:AI6) -> 16
A7: FRNLLincolnWCloverNRate500 | B7: LU_GEdwards | C7: WhiteClover | D7: 41935 | E7: 1 | F7: 500 | G7: 2014/15 | H7: Spring | I7: 1 | J7: Harvest | K7: 389 | M7: =IF(ISNUMBER(L7),L7/10,"") | N7: 1988.989 | O7: =IF(ISNUMBER(N7),N7/10,"") -> 198.8989 | P7: =IF(ISNUMBER(O7),SUMIFS(O$1:$O7,A$1:$A7,A7,C$1:$C7,C7,G$1:$G7,G7,E$1:$E7,E7),"") -> 198.8989 | U7: =IF(ISNUMBER(R7),R7/100,"") | V7: 18.687765 | W7: 13.853703 | X7: 73.911346 | Y7: 23.858343 | Z7: 86.045147 | AA7: 25.431559 | AB7: 0.040690494 | AC7: =IF(ISNUMBER(AB7),AB7,"") -> 0.040690494 | AD7: 11.825815 | AE7: 22.376126 | AH7: =IF(AND(ISNUMBER(AB7),ISNUMBER(O7)),ROUND(O7*AB7,3),"") -> 8.093 | AI7: =IF(ISNUMBER(AH7),SUMIFS($AH$1:AH7,$A$1:A7,A7,C$1:$C7,C7,$G$1:G7,G7,$E$1:E7,E7),"") -> 8.093 | AJ7: =COUNT(K7:AI7) -> 16
A8: FRNLLincolnWCloverNRate0 | B8: LU_GEdwards | C8: WhiteClover | D8: 41935 | E8: 2 | F8: 0 | G8: 2014/15 | H8: Spring | I8: 1 | J8: Harvest | K8: 0 | M8: =IF(ISNUMBER(L8),L8/10,"") | N8: 3126.0664 | O8: =IF(ISNUMBER(N8),N8/10,"") -> 312.60664 | P8: =IF(ISNUMBER(O8),SUMIFS(O$1:$O8,A$1:$A8,A8,C$1:$C8,C8,G$1:$G8,G8,E$1:$E8,E8),"") -> 312.60664 | U8: =IF(ISNUMBER(R8),R8/100,"") | V8: 19.957661 | W8: 15.20559 | X8: 76.56329 | Y8: 25.311842 | Z8: 88.709183 | AA8: 24.452002 | AB8: 0.039123203 | AC8: =IF(ISNUMBER(AB8),AB8,"") -> 0.039123203 | AD8: 12.250126 | AE8: 21.594538 | AH8: =IF(AND(ISNUMBER(AB8),ISNUMBER(O8)),ROUND(O8*AB8,3),"") -> 12.23 | AI8: =IF(ISNUMBER(AH8),SUMIFS($AH$1:AH8,$A$1:A8,A8,C$1:$C8,C8,$G$1:G8,G8,$E$1:E8,E8),"") -> 12.23 | AJ8: =COUNT(K8:AI8) -> 16
A9: FRNLLincolnWCloverNRate50 | B9: LU_GEdwards | C9: WhiteClover | D9: 41935 | E9: 2 | F9: 50 | G9: 2014/15 | H9: Spring | I9: 1 | J9: Harvest | K9: 45 | M9: =IF(ISNUMBER(L9),L9/10,"") | N9: 2262.0483 | O9: =IF(ISNUMBER(N9),N9/10,"") -> 226.20483 | P9: =IF(ISNUMBER(O9),SUMIFS(O$1:$O9,A$1:$A9,A9,C$1:$C9,C9,G$1:$G9,G9,E$1:$E9,E9),"") -> 226.20483 | U9: =IF(ISNUMBER(R9),R9/100,"") | V9: 18.104444 | W9: 15.62025 | X9: 80.367287 | Y9: 22.437314 | Z9: 87.633572 | AA9: 26.471241 | AB9: 0.042353986 | AC9: =IF(ISNUMBER(AB9),AB9,"") -> 0.042353986 | AD9: 12.858766 | AE9: 10.688178 | AH9: =IF(AND(ISNUMBER(AB9),ISNUMBER(O9)),ROUND(O9*AB9,3),"") -> 9.581 | AI9: =IF(ISNUMBER(AH9),SUMIFS($AH$1:AH9,$A$1:A9,A9,C$1:$C9,C9,$G$1:G9,G9,$E$1:E9,E9),"") -> 9.581 | AJ9: =COUNT(K9:AI9) -> 16
A10: FRNLLincolnWCloverNRate100 | B10: LU_GEdwards | C10: WhiteClover | D10: 41935 | E10: 2 | F10: 100 | G10: 2014/15 | H10: Spring | I10: 1 | J10: Harvest | K10: 78 | M10: =IF(ISNUMBER(L10),L10/10,"") | N10: 2924.9096 | O10: =IF(ISNUMBER(N10),N10/10,"") -> 292.49096 | P10: =IF(ISNUMBER(O10),SUMIFS(O$1:$O10,A$1:$A10,A10,C$1:$C10,C10,G$1:$G10,G10,E$1:$E10,E10),"") -> 292.49096 | U10: =IF(ISNUMBER(R10),R10/100,"") | V10: 20.72374 | W10: 13.989011 | X10: 73.833725 | Y10: 24.792643 | Z10: 86.301624 | AA10: 24.667459 | AB10: 0.039467934 | AC10: =IF(ISNUMBER(AB10),AB10,"") -> 0.039467934 | AD10: 11.813396 | AE10: 18.467222 | AH10: =IF(AND(ISNUMBER(AB10),ISNUMBER(O10)),ROUND(O10*AB10,3),"") -> 11.544 | AI10: =IF(ISNUMBER(AH10),SUMIFS($AH$1:AH10,$A$1:A10,A10,C$1:$C10,C10,$G$1:G10,G10,$E$1:E10,E10),"") -> 11.544 | AJ10: =COUNT(K10:AI10) -> 16
A11: FRNLLincolnWCloverNRate200 | B11: LU_GEdwards | C11: WhiteClover | D11: 41935 | E11: 2 | F11: 200 | G11: 2014/15 | H11: Spring | I11: 1 | J11: Harvest | K11: 156 | M11: =IF(ISNUMBER(L11),L11/10,"") | N11: 2705.8871 | O11: =IF(ISNUMBER(N11),N11/10,"") -> 270.58871 | P11: =IF(ISNUMBER(O11),SUMIFS(O$1:$O11,A$1:$A11,A11,C$1:$C11,C11,G$1:$G11,G11,E$1:$E11,E11),"") -> 270.58871 | U11: =IF(ISNUMBER(R11),R11/100,"") | V11: 21.229415 | W11: 12.924916 | X11: 74.825493 | Y11: 28.910044 | Z11: 89.033913 | AA11: 22.603944 | AB11: 0.03616631 | AC11: =IF(ISNUMBER(AB11),AB11,"") -> 0.03616631 | AD11: 11.972079 | AE11: 21.308861 | AH11: =IF(AND(ISNUMBER(AB11),ISNUMBER(O11)),ROUND(O11*AB11,3),"") -> 9.786 | AI11: =IF(ISNUMBER(AH11),SUMIFS($AH$1:AH11,$A$1:A11,A11,C$1:$C11,C11,$G$1:G11,G11,$E$1:E11,E11),"") -> 9.786 | AJ11: =COUNT(K11:AI11) -> 16
A12: FRNLLincolnWCloverNRate350 | B12: LU_GEdwards | C12: WhiteClover | D12: 41935 | E12: 2 | F12: 350 | G12: 2014/15 | H12: Spring | I12: 1 | J12: Harvest | K12: 272 | M12: =IF(ISNUMBER(L12),L12/10,"") | N12: 2808.961 | O12: =IF(ISNUMBER(N12),N12/10,"") -> 280.8961 | P12: =IF(ISNUMBER(O12),SUMIFS(O$1:$O12,A$1:$A12,A12,C$1:$C12,C12,G$1:$G12,G12,E$1:$E12,E12),"") -> 280.8961 | U12: =IF(ISNUMBER(R12),R12/100,"") | V12: 18.615002 | W12: 13.636625 | X12: 78.319218 | Y12: 23.450175 | Z12: 87.184296 | AA12: 27.272281 | AB12: 0.043635649 | AC12: =IF(ISNUMBER(AB12),AB12,"") -> 0.043635649 | AD12: 12.531075 | AE12: 18.852757 | AH12: =IF(AND(ISNUMBER(AB12),ISNUMBER(O12)),ROUND(O12*AB12,3),"") -> 12.257 | AI12: =IF(ISNUMBER(AH12),SUMIFS($AH$1:AH12,$A$1:A12,A12,C$1:$C12,C12,$G$1:G12,G12,$E$1:E12,E12),"") -> 12.257 | AJ12: =COUNT(K12:AI12) -> 16
A13: FRNLLincolnWCloverNRate500 | B13: LU_GEdwards | C13: WhiteClover | D13: 41935 | E13: 2 | F13: 500 | G13: 2014/15 | H13: Spring | I13: 1 | J13: Harvest | K13: 389 | M13: =IF(ISNUMBER(L13),L13/10,"") | N13: 3184.5026 | O13: =IF(ISNUMBER(N13),N13/10,"") -> 318.45026 | P13: =IF(ISNUMBER(O13),SUMIFS(O$1:$O13,A$1:$A13,A13,C$1:$C13,C13,G$1:$G13,G13,E$1:$E13,E13),"") -> 318.45026 | U13: =IF(ISNUMBER(R13),R13/100,"") | V13: 18.876146 | W13: 13.349252 | X13: 78.489323 | Y13: 22.933174 | Z13: 87.503529 | AA13: 26.612138 | AB13: 0.04257942 | AC13: =IF(ISNUMBER(AB13),AB13,"") -> 0.04257942 | AD13: 12.558292 | AE13: 18.622246 | AH13: =IF(AND(ISNUMBER(AB13),ISNUMBER(O13)),ROUND(O13*AB13,3),"") -> 13.559 | AI13: =IF(ISNUMBER(AH13),SUMIFS($AH$1:AH13,$A$1:A13,A13,C$1:$C13,C13,$G$1:G13,G13,$E$1:E13,E13),"") -> 13.559 | AJ13: =COUNT(K13:AI13) -> 16
... A121: FRNLLincolnWCloverNRate500 | B121: LU_GEdwards | C121: WhiteClover | D121: 42073 | E121: 4 | F121: 500 | G121: 2014/15 | H121: Autumn | I121: 5 | J121: Harvest | K121: 389 | M121: =IF(ISNUMBER(L121),L121/10,"") | N121: 972.18769 | O121: =IF(ISNUMBER(N121),N121/10,"") -> 97.218769 | P121: =IF(ISNUMBER(O121),SUMIFS(O$1:$O121,A$1:$A121,A121,C$1:$C121,C121,G$1:$G121,G121,E$1:$E121,E121),"") -> 1014.1175 | U121: =IF(ISNUMBER(R121),R121/100,"") | V121: 20.161551 | W121: 10.350018 | X121: 76.825428 | Y121: 26.595083 | Z121: 91.079933 | AA121: 29.19156 | AB121: 0.046706496 | AC121: =IF(ISNUMBER(AB121),AB121,"") -> 0.046706496 | AD121: 12.292068 | AE121: 11.243759 | AH121: =IF(AND(ISNUMBER(AB121),ISNUMBER(O121)),ROUND(O121*AB121,3),"") -> 4.541 | AI121: =IF(ISNUMBER(AH121),SUMIFS($AH$1:AH121,$A$1:A121,A121,C$1:$C121,C121,$G$1:G121,G121,$E$1:E121,E121),"") -> 41.717 | AJ121: =COUNT(K121:AI121) -> 16
A122: FRNLLincolnWCloverNRate0 | B122: LU_GEdwards | C122: WhiteClover | D122: 42080 | E122: 1 | F122: 0 | G122: 2014/15 | H122: Autumn | I122: 6 | J122: Regrowth1 | K122: 0 | L122: 498 | M122: =IF(ISNUMBER(L122),L122/10,"") -> 49.8 | O122: =IF(ISNUMBER(N122),N122/10,"") | P122: =IF(ISNUMBER(O122),SUMIFS(O$1:$O122,A$1:$A122,A122,C$1:$C122,C122,G$1:$G122,G122,E$1:$E122,E122),"") | U122: =IF(ISNUMBER(R122),R122/100,"") | V122: 19.628527 | W122: 2.1829565 | X122: 76.069237 | Y122: 29.554585 | Z122: 89.595165 | AA122: 30.852488 | AB122: 0.04936398 | AC122: =IF(ISNUMBER(AB122),AB122,"") -> 0.04936398 | AD122: 12.171078 | AE122: 15.949238 | AH122: =IF(AND(ISNUMBER(AB122),ISNUMBER(O122)),ROUND(O122*AB122,3),"") | AI122: =IF(ISNUMBER(AH122),SUMIFS($AH$1:AH122,$A$1:A122,A122,C$1:$C122,C122,$G$1:G122,G122,$E$1:E122,E122),"") | AJ122: =COUNT(K122:AI122) -> 13
A123: FRNLLincolnWCloverNRate50 | B123: LU_GEdwards | C123: WhiteClover | D123: 42080 | E123: 1 | F123: 50 | G123: 2014/15 | H123: Autumn | I123: 6 | J123: Regrowth1 | K123: 45 | L123: 473.75 | M123: =IF(ISNUMBER(L123),L123/10,"") -> 47.375 | O123: =IF(ISNUMBER(N123),N123/10,"") | P123: =IF(ISNUMBER(O123),SUMIFS(O$1:$O123,A$1:$A123,A123,C$1:$C123,C123,G$1:$G123,G123,E$1:$E123,E123),"") | U123: =IF(ISNUMBER(R123),R123/100,"") | V123: 16.900266 | W123: 10.451205 | X123: 81.152626 | Y123: 21.495842 | Z123: 89.883469 | AA123: 33.395521 | AB123: 0.053432834 | AC123: =IF(ISNUMBER(AB123),AB123,"") -> 0.053432834 | AD123: 12.98442 | AE123: 15.234303 | AH123: =IF(AND(ISNUMBER(AB123),ISNUMBER(O123)),ROUND(O123*AB123,3),"") | AI123: =IF(ISNUMBER(AH123),SUMIFS($AH$1:AH123,$A$1:A123,A123,C$1:$C123,C123,$G$1:G123,G123,$E$1:E123,E123),"") | AJ123: =COUNT(K123:AI123) -> 13
A124: FRNLLincolnWCloverNRate100 | B124: LU_GEdwards | C124: WhiteClover | D124: 42080 | E124: 1 | F124: 100 | G124: 2014/15 | H124: Autumn | I124: 6 | J124: Regrowth1 | K124: 78 | L124: 467.25 | M124: =IF(ISNUMBER(L124),L124/10,"") -> 46.725 | O124: =IF(ISNUMBER(N124),N124/10,"") | P124: =IF(ISNUMBER(O124),SUMIFS(O$1:$O124,A$1:$A124,A124,C$1:$C124,C124,G$1:$G124,G124,E$1:$E124,E124),"") | U124: =IF(ISNUMBER(R124),R124/100,"") | V124: 17.756351 | W124: 7.2514451 | X124: 81.382877 | Y124: 26.071842 | Z124: 90.595482 | AA124: 32.401825 | AB124: 0.05184292 | AC124: =IF(ISNUMBER(AB124),AB124,"") -> 0.05184292 | AD124: 13.02126 | AE124: 15.917508 | AH124: =IF(AND(ISNUMBER(AB124),ISNUMBER(O124)),ROUND(O124*AB124,3),"") | AI124: =IF(ISNUMBER(AH124),SUMIFS($AH$1:AH124,$A$1:A124,A124,C$1:$C124,C124,$G$1:G124,G124,$E$1:E124,E124),"") | AJ124: =COUNT(K124:AI124) -> 13
A125: FRNLLincolnWCloverNRate200 | B125: LU_GEdwards | C125: WhiteClover | D125: 42080 | E125: 1 | F125: 200 | G125: 2014/15 | H125: Autumn | I125: 6 | J125: Regrowth1 | K125: 156 | L125: 528 | M125: =IF(ISNUMBER(L125),L125/10,"") -> 52.8 | O125: =IF(ISNUMBER(N125),N125/10,"") | P125: =IF(ISNUMBER(O125),SUMIFS(O$1:$O125,A$1:$A125,A125,C$1:$C125,C125,G$1:$G125,G125,E$1:$E125,E125),"") | U125: =IF(ISNUMBER(R125),R125/100,"") | V125: 16.863671 | W125: 10.491496 | X125: 81.931278 | Y125: 23.998362 | Z125: 90.496269 | AA125: 33.408249 | AB125: 0.053453198 | AC125: =IF(ISNUMBER(AB125),AB125,"") -> 0.053453198 | AD125: 13.109005 | AE125: 15.134531 | AH125: =IF(AND(ISNUMBER(AB125),ISNUMBER(O125)),ROUND(O125*AB125,3),"") | AI125: =IF(ISNUMBER(AH125),SUMIFS($AH$1:AH125,$A$1:A125,A125,C$1:$C125,C125,$G$1:G125,G125,$E$1:E125,E125),"") | AJ125: =COUNT(K125:AI125) -> 13
A126: FRNLLincolnWCloverNRate350 | B126: LU_GEdwards | C126: WhiteClover | D126: 42080 | E126: 1 | F126: 350 | G126: 2014/15 | H126: Autumn | I126: 6 | J126: Regrowth1 | K126: 272 | L126: 508.25 | M126: =IF(ISNUMBER(L126),L126/10,"") -> 50.825 | O126: =IF(ISNUMBER(N126),N126/10,"") | P126: =IF(ISNUMBER(O126),SUMIFS(O$1:$O126,A$1:$A126,A126,C$1:$C126,C126,G$1:$G126,G126,E$1:$E126,E126),"") | U126: =IF(ISNUMBER(R126),R126/100,"") | V126: 16.863572 | W126: 10.855157 | X126: 80.61216 | Y126: 21.708484 | Z126: 89.934898 | AA126: 33.825102 | AB126: 0.054120163 | AC126: =IF(ISNUMBER(AB126),AB126,"") -> 0.054120163 | AD126: 12.897946 | AE126: 15.691628 | AH126: =IF(AND(ISNUMBER(AB126),ISNUMBER(O126)),ROUND(O126*AB126,3),"") | AI126: =IF(ISNUMBER(AH126),SUMIFS($AH$1:AH126,$A$1:A126,A126,C$1:$C126,C126,$G$1:G126,G126,$E$1:E126,E126),"") | AJ126: =COUNT(K126:AI126) -> 13
A127: FRNLLincolnWCloverNRate500 | B127: LU_GEdwards | C127: WhiteClover | D127: 42080 | E127: 1 | F127: 500 | G127: 2014/15 | H127: Autumn | I127: 6 | J127: Regrowth1 | K127: 389 | L127: 469 | M127: =IF(ISNUMBER(L127),L127/10,"") -> 46.9 | O127: =IF(ISNUMBER(N127),N127/10,"") | P127: =IF(ISNUMBER(O127),SUMIFS(O$1:$O127,A$1:$A127,A127,C$1:$C127,C127,G$1:$G127,G127,E$1:$E127,E127),"") | U127: =IF(ISNUMBER(R127),R127/100,"") | V127: 15.356926 | W127: 11.899849 | X127: 78.154068 | Y127: 22.534362 | Z127: 87.963779 | AA127: 33.588228 | AB127: 0.053741165 | AC127: =IF(ISNUMBER(AB127),AB127,"") -> 0.053741165 | AD127: 12.504651 | AE127: 17.66658 | AH127: =IF(AND(ISNUMBER(AB127),ISNUMBER(O127)),ROUND(O127*AB127,3),"") | AI127: =IF(ISNUMBER(AH127),SUMIFS($AH$1:AH127,$A$1:A127,A127,C$1:$C127,C127,$G$1:G127,G127,$E$1:E127,E127),"") | AJ127: =COUNT(K127:AI127) -> 13
A128: FRNLLincolnWCloverNRate0 | B128: LU_GEdwards | C128: WhiteClover | D128: 42080 | E128: 2 | F128: 0 | G128: 2014/15 | H128: Autumn | I128: 6 | J128: Regrowth1 | K128: 0 | L128: 530 | M128: =IF(ISNUMBER(L128),L128/10,"") -> 53 | O128: =IF(ISNUMBER(N128),N128/10,"") | P128: =IF(ISNUMBER(O128),SUMIFS(O$1:$O128,A$1:$A128,A128,C$1:$C128,C128,G$1:$G128,G128,E$1:$E128,E128),"") | U128: =IF(ISNUMBER(R128),R128/100,"") | V128: 18.425397 | W128: 13.51401 | X128: 78.733158 | Y128: 23.453491 | Z128: 89.815506 | AA128: 28.138532 | AB128: 0.045021651 | AC128: =IF(ISNUMBER(AB128),AB128,"") -> 0.045021651 | AD128: 12.597305 | AE128: 14.475418 | AH128: =IF(AND(ISNUMBER(AB128),ISNUMBER(O128)),ROUND(O128*AB128,3),"") | AI128: =IF(ISNUMBER(AH128),SUMIFS($AH$1:AH128,$A$1:A128,A128,C$1:$C128,C128,$G$1:G128,G128,$E$1:E128,E128),"") | AJ128: =COUNT(K128:AI128) -> 13
A129: FRNLLincolnWCloverNRate50 | B129: LU_GEdwards | C129: WhiteClover | D129: 42080 | E129: 2 | F129: 50 | G129: 2014/15 | H129: Autumn | I129: 6 | J129: Regrowth1 | K129: 45 | L129: 563.25 | M129: =IF(ISNUMBER(L129),L129/10,"") -> 56.325 | O129: =IF(ISNUMBER(N129),N129/10,"") | P129: =IF(ISNUMBER(O129),SUMIFS(O$1:$O129,A$1:$A129,A129,C$1:$C129,C129,G$1:$G129,G129,E$1:$E129,E129),"") | U129: =IF(ISNUMBER(R129),R129/100,"") | V129: 20.649205 | W129: 12.308624 | X129: 76.193302 | Y129: 26.735147 | Z129: 89.126755 | AA129: 26.652925 | AB129: 0.042644679 | AC129: =IF(ISNUMBER(AB129),AB129,"") -> 0.042644679 | AD129: 12.190928 | AE129: 12.091494 | AH129: =IF(AND(ISNUMBER(AB129),ISNUMBER(O129)),ROUND(O129*AB129,3),"") | AI129: =IF(ISNUMBER(AH129),SUMIFS($AH$1:AH129,$A$1:A129,A129,C$1:$C129,C129,$G$1:G129,G129,$E$1:E129,E129),"") | AJ129: =COUNT(K129:AI129) -> 13
A130: FRNLLincolnWCloverNRate100 | B130: LU_GEdwards | C130: WhiteClover | D130: 42080 | E130: 2 | F130: 100 | G130: 2014/15 | H130: Autumn | I130: 6 | J130: Regrowth1 | K130: 78 | L130: 594.25 | M130: =IF(ISNUMBER(L130),L130/10,"") -> 59.425 | O130: =IF(ISNUMBER(N130),N130/10,"") | P130: =IF(ISNUMBER(O130),SUMIFS(O$1:$O130,A$1:$A130,A130,C$1:$C130,C130,G$1:$G130,G130,E$1:$E130,E130),"") | U130: =IF(ISNUMBER(R130),R130/100,"") | V130: 18.900747 | W130: 14.423878 | X130: 78.898094 | Y130: 23.98114 | Z130: 89.984741 | AA130: 28.049005 | AB130: 0.044878407 | AC130: =IF(ISNUMBER(AB130),AB130,"") -> 0.044878407 | AD130: 12.623695 | AE130: 13.483188 | AH130: =IF(AND(ISNUMBER(AB130),ISNUMBER(O130)),ROUND(O130*AB130,3),"") | AI130: =IF(ISNUMBER(AH130),SUMIFS($AH$1:AH130,$A$1:A130,A130,C$1:$C130,C130,$G$1:G130,G130,$E$1:E130,E130),"") | AJ130: =COUNT(K130:AI130) -> 13
A131: FRNLLincolnWCloverNRate200 | B131: LU_GEdwards | C131: WhiteClover | D131: 42080 | E131: 2 | F131: 200 | G131: 2014/15 | H131: Autumn | I131: 6 | J131: Regrowth1 | K131: 156 | L131: 477.25 | M131: =IF(ISNUMBER(L131),L131/10,"") -> 47.725 | O131: =IF(ISNUMBER(N131),N131/10,"") | P131: =IF(ISNUMBER(O131),SUMIFS(O$1:$O131,A$1:$A131,A131,C$1:$C131,C131,G$1:$G131,G131,E$1:$E131,E131),"") | U131: =IF(ISNUMBER(R131),R131/100,"") | V131: 18.138078 | W131: 11.775459 | X131: 79.621372 | Y131: 24.818106 | Z131: 89.89917 | AA131: 30.839515 | AB131: 0.049343224 | AC131: =IF(ISNUMBER(AB131),AB131,"") -> 0.049343224 | AD131: 12.73942 | AE131: 16.762851 | AH131: =IF(AND(ISNUMBER(AB131),ISNUMBER(O131)),ROUND(O131*AB131,3),"") | AI131: =IF(ISNUMBER(AH131),SUMIFS($AH$1:AH131,$A$1:A131,A131,C$1:$C131,C131,$G$1:G131,G131,$E$1:E131,E131),"") | AJ131: =COUNT(K131:AI131) -> 13
A132: FRNLLincolnWCloverNRate350 | B132: LU_GEdwards | C132: WhiteClover | D132: 42080 | E132: 2 | F132: 350 | G132: 2014/15 | H132: Autumn | I132: 6 | J132: Regrowth1 | K132: 272 | L132: 486.75 | M132: =IF(ISNUMBER(L132),L132/10,"") -> 48.675 | O132: =IF(ISNUMBER(N132),N132/10,"") | P132: =IF(ISNUMBER(O132),SUMIFS(O$1:$O132,A$1:$A132,A132,C$1:$C132,C132,G$1:$G132,G132,E$1:$E132,E132),"") | U132: =IF(ISNUMBER(R132),R132/100,"") | V132: 22.095999 | W132: 12.923505 | X132: 75.673668 | Y132: 28.458647 | Z132: 89.825111 | AA132: 26.454332 | AB132: 0.042326932 | AC132: =IF(ISNUMBER(AB132),AB132,"") -> 0.042326932 | AD132: 12.107787 | AE132: 12.108849 | AH132: =IF(AND(ISNUMBER(AB132),ISNUMBER(O132)),ROUND(O132*AB132,3),"") | AI132: =IF(ISNUMBER(AH132),SUMIFS($AH$1:AH132,$A$1:A132,A132,C$1:$C132,C132,$G$1:G132,G132,$E$1:E132,E132),"") | AJ132: =COUNT(K132:AI132) -> 13
A133: FRNLLincolnWCloverNRate500 | B133: LU_GEdwards | C133: WhiteClover | D133: 42080 | E133: 2 | F133: 500 | G133: 2014/15 | H133: Autumn | I133: 6 | J133: Regrowth1 | K133: 389 | L133: 568.75 | M133: =IF(ISNUMBER(L133),L133/10,"") -> 56.875 | O133: =IF(ISNUMBER(N133),N133/10,"") | P133: =IF(ISNUMBER(O133),SUMIFS(O$1:$O133,A$1:$A133,A133,C$1:$C133,C133,G$1:$G133,G133,E$1:$E133,E133),"") | U133: =IF(ISNUMBER(R133),R133/100,"") | V133: 18.700193 | W133: 13.77898 | X133: 78.955498 | Y133: 23.63382 | Z133: 90.022106 | AA133: 27.481823 | AB133: 0.043970917 | AC133: =IF(ISNUMBER(AB133),AB133,"") -> 0.043970917 | AD133: 12.63288 | AE133: 13.980271 | AH133: =IF(AND(ISNUMBER(AB133),ISNUMBER(O133)),ROUND(O133*AB133,3),"") | AI133: =IF(ISNUMBER(AH133),SUMIFS($AH$1:AH133,$A$1:A133,A133,C$1:$C133,C133,$G$1:G133,G133,$E$1:E133,E133),"") | AJ133: =COUNT(K133:AI133) -> 13
... A175: FRNLLincolnWCloverNRate500 | B175: LU_GEdwards | C175: WhiteClover | D175: 42101 | E175: 3 | F175: 500 | G175: 2014/15 | H175: Autumn | I175: 6 | J175: Regrowth4 | K175: 389 | L175: 1339.75 | M175: =IF(ISNUMBER(L175),L175/10,"") -> 133.975 | O175: =IF(ISNUMBER(N175),N175/10,"") | P175: =IF(ISNUMBER(O175),SUMIFS(O$1:$O175,A$1:$A175,A175,C$1:$C175,C175,G$1:$G175,G175,E$1:$E175,E175),"") | U175: =IF(ISNUMBER(R175),R175/100,"") | V175: 17.018896 | W175: 16.081336 | X175: 82.240479 | Y175: 21.418386 | Z175: 91.458584 | AA175: 29.086256 | AB175: 0.04653801 | AC175: =IF(ISNUMBER(AB175),AB175,"") -> 0.04653801 | AD175: 13.158477 | AE175: 13.067774 | AH175: =IF(AND(ISNUMBER(AB175),ISNUMBER(O175)),ROUND(O175*AB175,3),"") | AI175: =IF(ISNUMBER(AH175),SUMIFS($AH$1:AH175,$A$1:A175,A175,C$1:$C175,C175,$G$1:G175,G175,$E$1:E175,E175),"") | AJ175: =COUNT(K175:AI175) -> 13
A176: FRNLLincolnWCloverNRate0 | B176: LU_GEdwards | C176: WhiteClover | D176: 42110 | E176: 1 | F176: 0 | G176: 2014/15 | H176: Autumn | I176: 6 | J176: Harvest | K176: 0 | M176: =IF(ISNUMBER(L176),L176/10,"") | N176: 1083.5035 | O176: =IF(ISNUMBER(N176),N176/10,"") -> 108.35035 | P176: =IF(ISNUMBER(O176),SUMIFS(O$1:$O176,A$1:$A176,A176,C$1:$C176,C176,G$1:$G176,G176,E$1:$E176,E176),"") -> 1087.2836 | U176: =IF(ISNUMBER(R176),R176/100,"") | V176: 20.44535 | W176: 9.3043776 | X176: 75.209766 | Y176: 24.620693 | Z176: 89.898693 | AA176: 30.77492 | AB176: 0.049239871 | AC176: =IF(ISNUMBER(AB176),AB176,"") -> 0.049239871 | AD176: 12.033563 | AE176: 10.405598 | AH176: =IF(AND(ISNUMBER(AB176),ISNUMBER(O176)),ROUND(O176*AB176,3),"") -> 5.335 | AI176: =IF(ISNUMBER(AH176),SUMIFS($AH$1:AH176,$A$1:A176,A176,C$1:$C176,C176,$G$1:G176,G176,$E$1:E176,E176),"") -> 44.642 | AJ176: =COUNT(K176:AI176) -> 16
A177: FRNLLincolnWCloverNRate50 | B177: LU_GEdwards | C177: WhiteClover | D177: 42110 | E177: 1 | F177: 50 | G177: 2014/15 | H177: Autumn | I177: 6 | J177: Harvest | K177: 45 | M177: =IF(ISNUMBER(L177),L177/10,"") | N177: 1104.1407 | O177: =IF(ISNUMBER(N177),N177/10,"") -> 110.41407 | P177: =IF(ISNUMBER(O177),SUMIFS(O$1:$O177,A$1:$A177,A177,C$1:$C177,C177,G$1:$G177,G177,E$1:$E177,E177),"") -> 1076.6947 | U177: =IF(ISNUMBER(R177),R177/100,"") | V177: 19.042478 | W177: 10.764045 | X177: 78.827686 | Y177: 25.828547 | Z177: 90.888466 | AA177: 32.138273 | AB177: 0.051421237 | AC177: =IF(ISNUMBER(AB177),AB177,"") -> 0.051421237 | AD177: 12.61243 | AE177: 11.645234 | AH177: =IF(AND(ISNUMBER(AB177),ISNUMBER(O177)),ROUND(O177*AB177,3),"") -> 5.678 | AI177: =IF(ISNUMBER(AH177),SUMIFS($AH$1:AH177,$A$1:A177,A177,C$1:$C177,C177,$G$1:G177,G177,$E$1:E177,E177),"") -> 46.153 | AJ177: =COUNT(K177:AI177) -> 16
A178: FRNLLincolnWCloverNRate100 | B178: LU_GEdwards | C178: WhiteClover | D178: 42110 | E178: 1 | F178: 100 | G178: 2014/15 | H178: Autumn | I178: 6 | J178: Harvest | K178: 78 | M178: =IF(ISNUMBER(L178),L178/10,"") | N178: 1266.9391 | O178: =IF(ISNUMBER(N178),N178/10,"") -> 126.69391 | P178: =IF(ISNUMBER(O178),SUMIFS(O$1:$O178,A$1:$A178,A178,C$1:$C178,C178,G$1:$G178,G178,E$1:$E178,E178),"") -> 1335.5137 | U178: =IF(ISNUMBER(R178),R178/100,"") | V178: 19.318915 | W178: 10.72861 | X178: 78.514328 | Y178: 25.035749 | Z178: 90.862427 | AA178: 31.201976 | AB178: 0.049923161 | AC178: =IF(ISNUMBER(AB178),AB178,"") -> 0.049923161 | AD178: 12.562292 | AE178: 12.368362 | AH178: =IF(AND(ISNUMBER(AB178),ISNUMBER(O178)),ROUND(O178*AB178,3),"") -> 6.325 | AI178: =IF(ISNUMBER(AH178),SUMIFS($AH$1:AH178,$A$1:A178,A178,C$1:$C178,C178,$G$1:G178,G178,$E$1:E178,E178),"") -> 56.552 | AJ178: =COUNT(K178:AI178) -> 16
A179: FRNLLincolnWCloverNRate200 | B179: LU_GEdwards | C179: WhiteClover | D179: 42110 | E179: 1 | F179: 200 | G179: 2014/15 | H179: Autumn | I179: 6 | J179: Harvest | K179: 156 | M179: =IF(ISNUMBER(L179),L179/10,"") | N179: 1001.1478 | O179: =IF(ISNUMBER(N179),N179/10,"") -> 100.11478 | P179: =IF(ISNUMBER(O179),SUMIFS(O$1:$O179,A$1:$A179,A179,C$1:$C179,C179,G$1:$G179,G179,E$1:$E179,E179),"") -> 1114.8764 | U179: =IF(ISNUMBER(R179),R179/100,"") | V179: 18.257664 | W179: 10.500724 | X179: 79.110157 | Y179: 24.594675 | Z179: 89.997864 | AA179: 31.339259 | AB179: 0.050142815 | AC179: =IF(ISNUMBER(AB179),AB179,"") -> 0.050142815 | AD179: 12.657625 | AE179: 11.262912 | AH179: =IF(AND(ISNUMBER(AB179),ISNUMBER(O179)),ROUND(O179*AB179,3),"") -> 5.02 | AI179: =IF(ISNUMBER(AH179),SUMIFS($AH$1:AH179,$A$1:A179,A179,C$1:$C179,C179,$G$1:G179,G179,$E$1:E179,E179),"") -> 47.339 | AJ179: =COUNT(K179:AI179) -> 16
A180: FRNLLincolnWCloverNRate350 | B180: LU_GEdwards | C180: WhiteClover | D180: 42110 | E180: 1 | F180: 350 | G180: 2014/15 | H180: Autumn | I180: 6 | J180: Harvest | K180: 272 | M180: =IF(ISNUMBER(L180),L180/10,"") | N180: 1194.5114 | O180: =IF(ISNUMBER(N180),N180/10,"") -> 119.45114 | P180: =IF(ISNUMBER(O180),SUMIFS(O$1:$O180,A$1:$A180,A180,C$1:$C180,C180,G$1:$G180,G180,E$1:$E180,E180),"") -> 1287.6485 | U180: =IF(ISNUMBER(R180),R180/100,"") | V180: 17.909807 | W180: 12.082251 | X180: 79.747612 | Y180: 21.793322 | Z180: 90.893654 | AA180: 31.826083 | AB180: 0.050921733 | AC180: =IF(ISNUMBER(AB180),AB180,"") -> 0.050921733 | AD180: 12.759618 | AE180: 12.377339 | AH180: =IF(AND(ISNUMBER(AB180),ISNUMBER(O180)),ROUND(O180*AB180,3),"") -> 6.083 | AI180: =IF(ISNUMBER(AH180),SUMIFS($AH$1:AH180,$A$1:A180,A180,C$1:$C180,C180,$G$1:G180,G180,$E$1:E180,E180),"") -> 54.525 | AJ180: =COUNT(K180:AI180) -> 16
A181: FRNLLincolnWCloverNRate500 | B181: LU_GEdwards | C181: WhiteClover | D181: 42110 | E181: 1 | F181: 500 | G181: 2014/15 | H181: Autumn | I181: 6 | J181: Harvest | K181: 389 | M181: =IF(ISNUMBER(L181),L181/10,"") | N181: 810.03492 | O181: =IF(ISNUMBER(N181),N181/10,"") -> 81.003492 | P181: =IF(ISNUMBER(O181),SUMIFS(O$1:$O181,A$1:$A181,A181,C$1:$C181,C181,G$1:$G181,G181,E$1:$E181,E181),"") -> 954.85513 | U181: =IF(ISNUMBER(R181),R181/100,"") | V181: 19.359761 | W181: 8.6443906 | X181: 76.581593 | Y181: 25.885168 | Z181: 90.600121 | AA181: 32.437356 | AB181: 0.05189977 | AC181: =IF(ISNUMBER(AB181),AB181,"") -> 0.05189977 | AD181: 12.253055 | AE181: 11.13798 | AH181: =IF(AND(ISNUMBER(AB181),ISNUMBER(O181)),ROUND(O181*AB181,3),"") -> 4.204 | AI181: =IF(ISNUMBER(AH181),SUMIFS($AH$1:AH181,$A$1:A181,A181,C$1:$C181,C181,$G$1:G181,G181,$E$1:E181,E181),"") -> 38.15 | AJ181: =COUNT(K181:AI181) -> 16
A182: FRNLLincolnWCloverNRate0 | B182: LU_GEdwards | C182: WhiteClover | D182: 42110 | E182: 2 | F182: 0 | G182: 2014/15 | H182: Autumn | I182: 6 | J182: Harvest | K182: 0 | M182: =IF(ISNUMBER(L182),L182/10,"") | N182: 905.03535 | O182: =IF(ISNUMBER(N182),N182/10,"") -> 90.503535 | P182: =IF(ISNUMBER(O182),SUMIFS(O$1:$O182,A$1:$A182,A182,C$1:$C182,C182,G$1:$G182,G182,E$1:$E182,E182),"") -> 1198.4175 | U182: =IF(ISNUMBER(R182),R182/100,"") | V182: 18.41635 | W182: 12.073822 | X182: 79.57991 | Y182: 25.90333 | Z182: 90.704384 | AA182: 31.49838 | AB182: 0.050397408 | AC182: =IF(ISNUMBER(AB182),AB182,"") -> 0.050397408 | AD182: 12.732786 | AE182: 11.878589 | AH182: =IF(AND(ISNUMBER(AB182),ISNUMBER(O182)),ROUND(O182*AB182,3),"") -> 4.561 | AI182: =IF(ISNUMBER(AH182),SUMIFS($AH$1:AH182,$A$1:A182,A182,C$1:$C182,C182,$G$1:G182,G182,$E$1:E182,E182),"") -> 48.948 | AJ182: =COUNT(K182:AI182) -> 16
A183: FRNLLincolnWCloverNRate50 | B183: LU_GEdwards | C183: WhiteClover | D183: 42110 | E183: 2 | F183: 50 | G183: 2014/15 | H183: Autumn | I183: 6 | J183: Harvest | K183: 45 | M183: =IF(ISNUMBER(L183),L183/10,"") | N183: 1106.3964 | O183: =IF(ISNUMBER(N183),N183/10,"") -> 110.63964 | P183: =IF(ISNUMBER(O183),SUMIFS(O$1:$O183,A$1:$A183,A183,C$1:$C183,C183,G$1:$G183,G183,E$1:$E183,E183),"") -> 1225.8862 | U183: =IF(ISNUMBER(R183),R183/100,"") | V183: 18.312548 | W183: 12.390318 | X183: 80.904781 | Y183: 23.199978 | Z183: 90.28088 | AA183: 30.820584 | AB183: 0.049312935 | AC183: =IF(ISNUMBER(AB183),AB183,"") -> 0.049312935 | AD183: 12.944765 | AE183: 11.881188 | AH183: =IF(AND(ISNUMBER(AB183),ISNUMBER(O183)),ROUND(O183*AB183,3),"") -> 5.456 | AI183: =IF(ISNUMBER(AH183),SUMIFS($AH$1:AH183,$A$1:A183,A183,C$1:$C183,C183,$G$1:G183,G183,$E$1:E183,E183),"") -> 50.982 | AJ183: =COUNT(K183:AI183) -> 16
A184: FRNLLincolnWCloverNRate100 | B184: LU_GEdwards | C184: WhiteClover | D184: 42110 | E184: 2 | F184: 100 | G184: 2014/15 | H184: Autumn | I184: 6 | J184: Harvest | K184: 78 | M184: =IF(ISNUMBER(L184),L184/10,"") | N184: 958.55139 | O184: =IF(ISNUMBER(N184),N184/10,"") -> 95.855139 | P184: =IF(ISNUMBER(O184),SUMIFS(O$1:$O184,A$1:$A184,A184,C$1:$C184,C184,G$1:$G184,G184,E$1:$E184,E184),"") -> 1176.0184 | U184: =IF(ISNUMBER(R184),R184/100,"") | V184: 18.81282 | W184: 11.642881 | X184: 78.657314 | Y184: 25.284966 | Z184: 90.140705 | AA184: 29.357732 | AB184: 0.046972371 | AC184: =IF(ISNUMBER(AB184),AB184,"") -> 0.046972371 | AD184: 12.58517 | AE184: 13.634567 | AH184: =IF(AND(ISNUMBER(AB184),ISNUMBER(O184)),ROUND(O184*AB184,3),"") -> 4.503 | AI184: =IF(ISNUMBER(AH184),SUMIFS($AH$1:AH184,$A$1:A184,A184,C$1:$C184,C184,$G$1:G184,G184,$E$1:E184,E184),"") -> 45.863 | AJ184: =COUNT(K184:AI184) -> 16
A185: FRNLLincolnWCloverNRate200 | B185: LU_GEdwards | C185: WhiteClover | D185: 42110 | E185: 2 | F185: 200 | G185: 2014/15 | H185: Autumn | I185: 6 | J185: Harvest | K185: 156 | M185: =IF(ISNUMBER(L185),L185/10,"") | N185: 1009.5664 | O185: =IF(ISNUMBER(N185),N185/10,"") -> 100.95664 | P185: =IF(ISNUMBER(O185),SUMIFS(O$1:$O185,A$1:$A185,A185,C$1:$C185,C185,G$1:$G185,G185,E$1:$E185,E185),"") -> 1248.625 | U185: =IF(ISNUMBER(R185),R185/100,"") | V185: 19.238148 | W185: 12.683769 | X185: 79.373859 | Y185: 26.811281 | Z185: 90.98896 | AA185: 30.451676 | AB185: 0.048722682 | AC185: =IF(ISNUMBER(AB185),AB185,"") -> 0.048722682 | AD185: 12.699818 | AE185: 11.250475 | AH185: =IF(AND(ISNUMBER(AB185),ISNUMBER(O185)),ROUND(O185*AB185,3),"") -> 4.919 | AI185: =IF(ISNUMBER(AH185),SUMIFS($AH$1:AH185,$A$1:A185,A185,C$1:$C185,C185,$G$1:G185,G185,$E$1:E185,E185),"") -> 50.494 | AJ185: =COUNT(K185:AI185) -> 16
A186: FRNLLincolnWCloverNRate350 | B186: LU_GEdwards | C186: WhiteClover | D186: 42110 | E186: 2 | F186: 350 | G186: 2014/15 | H186: Autumn | I186: 6 | J186: Harvest | K186: 272 | M186: =IF(ISNUMBER(L186),L186/10,"") | N186: 910.23802 | O186: =IF(ISNUMBER(N186),N186/10,"") -> 91.023802 | P186: =IF(ISNUMBER(O186),SUMIFS(O$1:$O186,A$1:$A186,A186,C$1:$C186,C186,G$1:$G186,G186,E$1:$E186,E186),"") -> 1265.8413 | U186: =IF(ISNUMBER(R186),R186/100,"") | V186: 17.427291 | W186: 13.672369 | X186: 82.349159 | Y186: 24.61017 | Z186: 92.303097 | AA186: 32.290599 | AB186: 0.051664958 | AC186: =IF(ISNUMBER(AB186),AB186,"") -> 0.051664958 | AD186: 13.175865 | AE186: 11.687159 | AH186: =IF(AND(ISNUMBER(AB186),ISNUMBER(O186)),ROUND(O186*AB186,3),"") -> 4.703 | AI186: =IF(ISNUMBER(AH186),SUMIFS($AH$1:AH186,$A$1:A186,A186,C$1:$C186,C186,$G$1:G186,G186,$E$1:E186,E186),"") -> 52.953 | AJ186: =COUNT(K186:AI186) -> 16
A187: FRNLLincolnWCloverNRate500 | B187: LU_GEdwards | C187: WhiteClover | D187: 42110 | E187: 2 | F187: 500 | G187: 2014/15 | H187: Autumn | I187: 6 | J187: Harvest | K187: 389 | M187: =IF(ISNUMBER(L187),L187/10,"") | N187: 1203.2964 | O187: =IF(ISNUMBER(N187),N187/10,"") -> 120.32964 | P187: =IF(ISNUMBER(O187),SUMIFS(O$1:$O187,A$1:$A187,A187,C$1:$C187,C187,G$1:$G187,G187,E$1:$E187,E187),"") -> 1379.3795 | U187: =IF(ISNUMBER(R187),R187/100,"") | V187: 18.117456 | W187: 13.385537 | X187: 79.989746 | Y187: 25.542837 | Z187: 90.773239 | AA187: 30.260238 | AB187: 0.04841638 | AC187: =IF(ISNUMBER(AB187),AB187,"") -> 0.04841638 | AD187: 12.798359 | AE187: 11.018558 | AH187: =IF(AND(ISNUMBER(AB187),ISNUMBER(O187)),ROUND(O187*AB187,3),"") -> 5.826 | AI187: =IF(ISNUMBER(AH187),SUMIFS($AH$1:AH187,$A$1:A187,A187,C$1:$C187,C187,$G$1:G187,G187,$E$1:E187,E187),"") -> 57.885 | AJ187: =COUNT(K187:AI187) -> 16
... A247: FRNLLincolnWCloverNRate500 | B247: LU_GEdwards | C247: WhiteClover | D247: 42283 | E247: 4 | F247: 500 | G247: 2015/16 | H247: Spring | I247: 1 | J247: Harvest | K247: 389 | M247: =IF(ISNUMBER(L247),L247/10,"") | N247: 1917.0549 | O247: =IF(ISNUMBER(N247),N247/10,"") -> 191.70549 | P247: =IF(ISNUMBER(O247),SUMIFS(O$1:$O247,A$1:$A247,A247,C$1:$C247,C247,G$1:$G247,G247,E$1:$E247,E247),"") -> 191.70549 | U247: =IF(ISNUMBER(R247),R247/100,"") | V247: 18.717206 | W247: 13.58287 | X247: 78.0686 | Y247: 24.520387 | Z247: 89.575298 | AA247: 28.100048 | AB247: 0.044960077 | AC247: =IF(ISNUMBER(AB247),AB247,"") -> 0.044960077 | AD247: 12.490976 | AE247: 13.253383 | AH247: =IF(AND(ISNUMBER(AB247),ISNUMBER(O247)),ROUND(O247*AB247,3),"") -> 8.619 | AI247: =IF(ISNUMBER(AH247),SUMIFS($AH$1:AH247,$A$1:A247,A247,C$1:$C247,C247,$G$1:G247,G247,$E$1:E247,E247),"") -> 8.619 | AJ247: =COUNT(K247:AI247) -> 16
...

Sheet ObservedSpeciesMeans
A1: SimulationName | B1: Source | C1: ForageTreat | D1: Date | E1: Rep | F1: NRate | G1: GrowthSeason | H1: Season | I1: RegrowthRotation | J1: EvalStage | K1: ActualNRate | L1: AboveGroundWt_kgha | M1: AbovegroundWt | N1: HarvestedWt_kgha | O1: DefoliatedWt | P1: CumDefoliatedWt | Q1: WhiteClover.Population | R1: WhiteCloverFraction | S1: OtherSpeciesFraction | T1: DeadMaterialFraction | U1: CloverContent | V1: ADF % | W1: WSC% | X1: DOMD% | Y1: NDF% | Z1: OM% | AA1: CP% | AB1: HerbageNConc | AC1: AbovegroundLive.NConc | AD1: ME | AE1: DMcontent | AF1: LAI | AG1: LightExtinctionCoefficient | AH1: DefoliatedN | AI1: CumDefoliatedN | AJ1: COUNT | AK1: Nvals
A2: FRNLLincolnWCloverNRate0 | B2: LU_GEdwards | C2: WhiteClover | D2: 41935 | E2: 1 | F2: 0 | G2: 2014/15 | H2: Spring | I2: 1 | J2: Harvest | K2: =IF(ISNUMBER(AVERAGEIFS(ObservedSpeciesData!K$2:K$4955,ObservedSpeciesData!$A$2:$A$4955,$A2,ObservedSpeciesData!$D$2:$D$4955,$D2)),AVERAGEIFS(ObservedSpeciesData!K$2:K$4955,ObservedSpeciesData!$A$2:$A$4955,$A2,ObservedSpeciesData!$D$2:$D$4955,$D2),"") -> 0 | L2: =IF(ISNUMBER(AVERAGEIFS(ObservedSpeciesData!L$2:L$4955,ObservedSpeciesData!$A$2:$A$4955,$A2,ObservedSpeciesData!$D$2:$D$4955,$D2)),AVERAGEIFS(ObservedSpeciesData!L$2:L$4955,ObservedSpeciesData!$A$2:$A$4955,$A2,ObservedSpeciesData!$D$2:$D$4955,$D2),"") | M2: =IF(ISNUMBER(AVERAGEIFS(ObservedSpeciesData!M$2:M$4955,ObservedSpeciesData!$A$2:$A$4955,$A2,ObservedSpeciesData!$D$2:$D$4955,$D2)),AVERAGEIFS(ObservedSpeciesData!M$2:M$4955,ObservedSpeciesData!$A$2:$A$4955,$A2,ObservedSpeciesData!$D$2:$D$4955,$D2),"") | N2: =IF(ISNUMBER(AVERAGEIFS(ObservedSpeciesData!N$2:N$4955,ObservedSpeciesData!$A$2:$A$4955,$A2,ObservedSpeciesData!$D$2:$D$4955,$D2)),AVERAGEIFS(ObservedSpeciesData!N$2:N$4955,ObservedSpeciesData!$A$2:$A$4955,$A2,ObservedSpeciesData!$D$2:$D$4955,$D2),"") -> 2003.8844 | O2: =IF(ISNUMBER(AVERAGEIFS(ObservedSpeciesData!O$2:O$4955,ObservedSpeciesData!$A$2:$A$4955,$A2,ObservedSpeciesData!$D$2:$D$4955,$D2)),AVERAGEIFS(ObservedSpeciesData!O$2:O$4955,ObservedSpeciesData!$A$2:$A$4955,$A2,ObservedSpeciesData!$D$2:$D$4955,$D2),"") -> 200.38844 | P2: =IF(ISNUMBER(AVERAGEIFS(ObservedSpeciesData!P$2:P$4955,ObservedSpeciesData!$A$2:$A$4955,$A2,ObservedSpeciesData!$C$2:$C$4955,$C2,ObservedSpeciesData!$D$2:$D$4955,$D2)),AVERAGEIFS(ObservedSpeciesData!P$2:P$4955,ObservedSpeciesData!$A$2:$A$4955,$A2,ObservedSpeciesData!$C$2:$C$4955,$C2,ObservedSpeciesData!$D$2:$D$4955,$D2),"") -> 200.38844 | R2: =IF(ISNUMBER(AVERAGEIFS(ObservedSpeciesData!R$2:R$4955,ObservedSpeciesData!$A$2:$A$4955,$A2,ObservedSpeciesData!$D$2:$D$4955,$D2)),AVERAGEIFS(ObservedSpeciesData!R$2:R$4955,ObservedSpeciesData!$A$2:$A$4955,$A2,ObservedSpeciesData!$D$2:$D$4955,$D2),"") | S2: =IF(ISNUMBER(AVERAGEIFS(ObservedSpeciesData!S$2:S$4955,ObservedSpeciesData!$A$2:$A$4955,$A2,ObservedSpeciesData!$D$2:$D$4955,$D2)),AVERAGEIFS(ObservedSpeciesData!S$2:S$4955,ObservedSpeciesData!$A$2:$A$4955,$A2,ObservedSpeciesData!$D$2:$D$4955,$D2),"") | T2: =IF(ISNUMBER(AVERAGEIFS(ObservedSpeciesData!T$2:T$4955,ObservedSpeciesData!$A$2:$A$4955,$A2,ObservedSpeciesData!$D$2:$D$4955,$D2)),AVERAGEIFS(ObservedSpeciesData!T$2:T$4955,ObservedSpeciesData!$A$2:$A$4955,$A2,ObservedSpeciesData!$D$2:$D$4955,$D2),"") | U2: =IF(ISNUMBER(AVERAGEIFS(ObservedSpeciesData!U$2:U$4955,ObservedSpeciesData!$A$2:$A$4955,$A2,ObservedSpeciesData!$C$2:$C$4955,$C2,ObservedSpeciesData!$D$2:$D$4955,$D2)),AVERAGEIFS(ObservedSpeciesData!U$2:U$4955,ObservedSpeciesData!$A$2:$A$4955,$A2,ObservedSpeciesData!$C$2:$C$4955,$C2,ObservedSpeciesData!$D$2:$D$4955,$D2),"") | V2: =IF(ISNUMBER(AVERAGEIFS(ObservedSpeciesData!V$2:V$4955,ObservedSpeciesData!$A$2:$A$4955,$A2,ObservedSpeciesData!$D$2:$D$4955,$D2)),AVERAGEIFS(ObservedSpeciesData!V$2:V$4955,ObservedSpeciesData!$A$2:$A$4955,$A2,ObservedSpeciesData!$D$2:$D$4955,$D2),"") -> 20.139729 | W2: =IF(ISNUMBER(AVERAGEIFS(ObservedSpeciesData!W$2:W$4955,ObservedSpeciesData!$A$2:$A$4955,$A2,ObservedSpeciesData!$D$2:$D$4955,$D2)),AVERAGEIFS(ObservedSpeciesData!W$2:W$4955,ObservedSpeciesData!$A$2:$A$4955,$A2,ObservedSpeciesData!$D$2:$D$4955,$D2),"") -> 14.024068 | X2: =IF(ISNUMBER(AVERAGEIFS(ObservedSpeciesData!X$2:X$4955,ObservedSpeciesData!$A$2:$A$4955,$A2,ObservedSpeciesData!$D$2:$D$4955,$D2)),AVERAGEIFS(ObservedSpeciesData!X$2:X$4955,ObservedSpeciesData!$A$2:$A$4955,$A2,ObservedSpeciesData!$D$2:$D$4955,$D2),"") -> 76.616493 | Y2: =IF(ISNUMBER(AVERAGEIFS(ObservedSpeciesData!Y$2:Y$4955,ObservedSpeciesData!$A$2:$A$4955,$A2,ObservedSpeciesData!$D$2:$D$4955,$D2)),AVERAGEIFS(ObservedSpeciesData!Y$2:Y$4955,ObservedSpeciesData!$A$2:$A$4955,$A2,ObservedSpeciesData!$D$2:$D$4955,$D2),"") -> 26.252035 | Z2: =IF(ISNUMBER(AVERAGEIFS(ObservedSpeciesData!Z$2:Z$4955,ObservedSpeciesData!$A$2:$A$4955,$A2,ObservedSpeciesData!$D$2:$D$4955,$D2)),AVERAGEIFS(ObservedSpeciesData!Z$2:Z$4955,ObservedSpeciesData!$A$2:$A$4955,$A2,ObservedSpeciesData!$D$2:$D$4955,$D2),"") -> 88.393574 | AA2: =IF(ISNUMBER(AVERAGEIFS(ObservedSpeciesData!AA$2:AA$4955,ObservedSpeciesData!$A$2:$A$4955,$A2,ObservedSpeciesData!$D$2:$D$4955,$D2)),AVERAGEIFS(ObservedSpeciesData!AA$2:AA$4955,ObservedSpeciesData!$A$2:$A$4955,$A2,ObservedSpeciesData!$D$2:$D$4955,$D2),"") -> 25.42699 | AB2: =IF(ISNUMBER(AVERAGEIFS(ObservedSpeciesData!AB$2:AB$4955,ObservedSpeciesData!$A$2:$A$4955,$A2,ObservedSpeciesData!$D$2:$D$4955,$D2)),AVERAGEIFS(ObservedSpeciesData!AB$2:AB$4955,ObservedSpeciesData!$A$2:$A$4955,$A2,ObservedSpeciesData!$D$2:$D$4955,$D2),"") -> 0.040683184 | AC2: =IF(ISNUMBER(AVERAGEIFS(ObservedSpeciesData!AC$2:AC$4955,ObservedSpeciesData!$A$2:$A$4955,$A2,ObservedSpeciesData!$D$2:$D$4955,$D2)),AVERAGEIFS(ObservedSpeciesData!AC$2:AC$4955,ObservedSpeciesData!$A$2:$A$4955,$A2,ObservedSpeciesData!$D$2:$D$4955,$D2),"") -> 0.040683184 | ... AE2: =IF(ISNUMBER(AVERAGEIFS(ObservedSpeciesData!AE$2:AE$4955,ObservedSpeciesData!$A$2:$A$4955,$A2,ObservedSpeciesData!$D$2:$D$4955,$D2)),AVERAGEIFS(ObservedSpeciesData!AE$2:AE$4955,ObservedSpeciesData!$A$2:$A$4955,$A2,ObservedSpeciesData!$D$2:$D$4955,$D2),"") -> 20.946009 | AH2: =IF(ISNUMBER(AVERAGEIFS(ObservedSpeciesData!AH$2:AH$4955,ObservedSpeciesData!$A$2:$A$4955,$A2,ObservedSpeciesData!$D$2:$D$4955,$D2)),AVERAGEIFS(ObservedSpeciesData!AH$2:AH$4955,ObservedSpeciesData!$A$2:$A$4955,$A2,ObservedSpeciesData!$D$2:$D$4955,$D2),"") -> 7.974 | AI2: =IF(ISNUMBER(AVERAGEIFS(ObservedSpeciesData!AI$2:AI$4955,ObservedSpeciesData!$A$2:$A$4955,$A2,ObservedSpeciesData!$C$2:$C$4955,$C2,ObservedSpeciesData!$D$2:$D$4955,$D2)),AVERAGEIFS(ObservedSpeciesData!AI$2:AI$4955,ObservedSpeciesData!$A$2:$A$4955,$A2,ObservedSpeciesData!$C$2:$C$4955,$C2,ObservedSpeciesData!$D$2:$D$4955,$D2),"") -> 7.974 | AJ2: =COUNTIFS(ObservedSpeciesData!$A$2:$A$828,$A2,ObservedSpeciesData!$D$2:$D$828,$D2) -> 4 | AK2: =COUNT(M2:AI2) -> 15
